Workbook

Sheet US Macro Data
A1: Date (Quarterly) | B1: GDP YoY % Change | C1: PMI | D1: CPI | E1: Core CPI | F1: Unemployment Levels % | I1: Consensus Forecast | K1: GDP | L1: PMI | M1: CPI F | N1: Core CPI | O1: Unemployment | Q1: Surprise | R1: GDP | S1: PMI | T1: CPI | U1: Core CPI | V1: Unemployment
A2: 38718 | B2: 3.21311 | D2: 3.69087 | E2: 2.5043677 | F2: 4.7 | K2: 5.9343483 | M2: 2.23 | N2: 1.2 | O2: 4.85 | R2: =B2-K2 -> -2.7212383 | S2: =C2-L2 -> 0 | T2: =D2-M2 -> 1.46087 | U2: =E2-N2 -> 1.3043677 | V2: =F2-O2 -> -0.15
A3: 38808 | B3: 2.9729 | D3: 3.92427 | E3: 2.8276603 | F3: 4.6 | K3: 5.6644324 | M3: 3.28 | N3: 1.4 | O3: 4.7 | R3: =B3-K3 -> -2.6915324 | S3: =C3-L3 -> 0 | T3: =D3-M3 -> 0.64427 | U3: =E3-N3 -> 1.4276603 | V3: =F3-O3 -> -0.1
A4: 38899 | B4: 2.32528 | D4: 3.34012 | E4: 3.1720473 | F4: 4.6 | K4: 5.5768131 | M4: 3.37 | N4: 1.5 | O4: 4.72 | R4: =B4-K4 -> -3.2515331 | S4: =C4-L4 -> 0 | T4: =D4-M4 -> -0.02988 | U4: =E4-N4 -> 1.6720473 | V4: =F4-O4 -> -0.12
A5: 38991 | B5: 2.63456 | D5: 1.9654 | E5: 3.18104 | F5: 4.4 | K5: 5.1370808 | M5: 0.52 | N5: 1.5 | O5: 4.59 | R5: =B5-K5 -> -2.5025208 | S5: =C5-L5 -> 0 | T5: =D5-M5 -> 1.4454 | U5: =E5-N5 -> 1.68104 | V5: =F5-O5 -> -0.19
A6: 39083 | B6: 1.57672 | D6: 2.43165 | E6: 3.1296833 | F6: 4.5 | K6: 5.1558185 | M6: 2.33 | N6: 2.23 | O6: 4.6 | R6: =B6-K6 -> -3.5790985 | S6: =C6-L6 -> 0 | T6: =D6-M6 -> 0.10165 | U6: =E6-N6 -> 0.89968333 | V6: =F6-O6 -> -0.1
A7: 39173 | B7: 1.93437 | D7: 2.66529 | E7: 2.7844593 | F7: 4.5 | K7: 5.1996482 | M7: 4.07 | N7: 2.2 | O7: 4.56 | R7: =B7-K7 -> -3.2652782 | S7: =C7-L7 -> 0 | T7: =D7-M7 -> -1.40471 | U7: =E7-N7 -> 0.58445933 | V7: =F7-O7 -> -0.06
A8: 39264 | B8: 2.36804 | D8: 2.34897 | E8: 2.4864963 | F8: 4.7 | K8: 4.8464889 | M8: 2.33 | N8: 2.25 | O8: 4.6 | R8: =B8-K8 -> -2.4784489 | S8: =C8-L8 -> 0 | T8: =D8-M8 -> 0.01897 | U8: =E8-N8 -> 0.23649633 | V8: =F8-O8 -> 0.1
A9: 39356 | B9: 2.13336 | D9: 4.03114 | E9: 2.6188327 | F9: 4.8 | K9: 4.4958039 | M9: 2.89 | N9: 2.16 | O9: 4.74 | R9: =B9-K9 -> -2.3624439 | S9: =C9-L9 -> 0 | T9: =D9-M9 -> 1.14114 | U9: =E9-N9 -> 0.45883267 | V9: =F9-O9 -> 0.06
A10: 39448 | B10: 1.39247 | D10: 4.13704 | E10: 2.684794 | F10: 5 | K10: 3.9788502 | M10: 3.2 | N10: 2.33 | O10: 5 | R10: =B10-K10 -> -2.5863802 | S10: =C10-L10 -> 0 | T10: =D10-M10 -> 0.93704 | U10: =E10-N10 -> 0.354794 | V10: =F10-O10 -> 0
A11: 39539 | B11: 1.37601 | D11: 4.31042 | E11: 2.817493 | F11: 5.3 | K11: 4.081243 | M11: 3.51 | N11: 2.25 | O11: 5.15 | R11: =B11-K11 -> -2.705233 | S11: =C11-L11 -> 0 | T11: =D11-M11 -> 0.80042 | U11: =E11-N11 -> 0.567493 | V11: =F11-O11 -> 0.15
A12: 39630 | B12: 0.26597 | D12: 5.2525 | E12: 3.0542993 | F12: 6 | K12: 3.9885369 | M12: 5.12 | N12: 2.52 | O12: 5.65 | R12: =B12-K12 -> -3.7225669 | S12: =C12-L12 -> 0 | T12: =D12-M12 -> 0.1325 | U12: =E12-N12 -> 0.53429933 | V12: =F12-O12 -> 0.35
A13: 39722 | B13: -2.54115 | D13: 1.5958 | E13: 2.7712737 | F13: 6.9 | K13: 1.5463879 | M13: -2.32 | N13: 2.05 | O13: 6.61 | R13: =B13-K13 -> -4.0875379 | S13: =C13-L13 -> 0 | T13: =D13-M13 -> 3.9158 | U13: =E13-N13 -> 0.72127367 | V13: =F13-O13 -> 0.29
... A81: 45931 | B81: 2.03257 | D81: 2.82997 | E81: 3.0129871 | F81: 4.5 | K81: 4.3384945 | M81: 3.07 | N81: 3.17 | O81: 4.4 | R81: =B81-K81 -> -2.3059245 | S81: =C81-L81 -> 0 | T81: =D81-M81 -> -0.24003 | U81: =E81-N81 -> -0.15701293 | V81: =F81-O81 -> 0.1
A82: 46023 | K82: 4.992656 | M82: 2.69 | N82: 2.72 | O82: 4.42 | R82: =B82-K82 -> -4.992656 | S82: =C82-L82 -> 0 | T82: =D82-M82 -> -2.69 | U82: =E82-N82 -> -2.72 | V82: =F82-O82 -> -4.42
A83: 46113
A84: 46204

Sheet US Macro Scoring 
B3: Growth Scoring | F3: Inflation Scoring | J3: Labor Scoring
B5: Level (GDP) Score | C5: =(((C7-C8)/C9)*C38) -> -0.41802289 | F5: Level (CPI) Score | G5: =((G7-G8)/G9)*G38 -> 0.063276291 | J5: Level (Unemployment) | K5: =(((K7-K8)/K9)*K38) -> 0.63601115
B7: GDP (Actual) | C7: 1.10765 | F7: CPI (Actual) | G7: 2.434 | J7: Unemployment (Actual) | K7: 4.4
B8: Historical Average | C8: =AVERAGE('US Macro Data'!B2:B81) -> 2.0449501 | F8: Historical Average | G8: =AVERAGE('US Macro Data'!D2:D81) -> 2.5539266 | J8: Historical Average | K8: =AVERAGE('US Macro Data'!F2:F81) -> 5.77125
B9: Standard Deviation | C9: =_xlfn.STDEV.S('US Macro Data'!B2:B81) -> 2.242222 | F9: Standard Deviation | G9: =_xlfn.STDEV.S('US Macro Data'!D2:D81) -> 1.8952853 | J9: Standard Deviation | K9: =_xlfn.STDEV.S('US Macro Data'!F2:F81) -> 2.1560157
B11: Level (PMI) Score | F11: Level (Core CPI) Score | G11: =(((G13-G14)/G15)*G38) -> -0.17899384
B13: PMI (Actual) | C13: 52.7 | F13: Core CPI (Actual) | G13: 2.90391
B14: Historical Average | C14: =AVERAGE('US Macro Data'!C2:C81) -> #DIV/0! | F14: Historical Average | G14: =AVERAGE('US Macro Data'!E2:E81) -> 2.6885889
B15: Standard Deviation | C15: =_xlfn.STDEV.S('US Macro Data'!C2:C81) -> #DIV/0! | F15: Standard Deviation | G15: =_xlfn.STDEV.S('US Macro Data'!E2:E81) -> 1.2029524
B17: Surprise (GDP) Score | C17: =((C20-C21)/C22)*C38 -> -0.89461986 | F17: Surprise (CPI) Score | G17: =((G20-G21)/G22)*G38 -> 0.29383555 | J17: Surprise (Unemployment) | K17: =(((K20-K21)/K22)) -> 0.21009188
B19: GDP Forecast | C19: 4.992656 | F19: CPI Forecast | G19: 2.69 | J19: Unemployment Forecast | K19: 4.42
B20: GDP Current Surprise | C20: =C7-C19 -> -3.885006 | F20: CPI Current Surprise | G20: =G7-G19 -> -0.256 | J20: Unemployment Current Surprise | K20: =K7-K19 -> -0.02
B21: Average Surprise | C21: =AVERAGE('US Macro Data'!R2:R82) -> -2.5690145 | F21: Average Surprise | G21: =AVERAGE('US Macro Data'!T2:T82) -> 0.21054481 | J21: Average Surprise | K21: =AVERAGE('US Macro Data'!V2:V82) -> -0.14790123
B22: Standard Deviation | C22: =_xlfn.STDEV.S('US Macro Data'!K2:K82) -> 1.4710064 | F22: Standard Deviation | G22: =_xlfn.STDEV.S('US Macro Data'!M2:M82) -> 1.5877753 | J22: Standard Deviation | K22: =_xlfn.STDEV.S('US Macro Data'!V2:V82) -> 0.60878715
B24: Surprise (PMI) Score | F24: Surprise (Core CPI) Score | G24: =((G27-G28)/G29)*G38 -> 0.25308932 | J24: Unemployment is unique case because directional variable is -1 but its average is negative
J25: In this case the actual was less forecast and the double negative makes it positive but the directional variable makes it negative again even though this lower than expected unemployment is positive for the macro environment
F26: Core CPI Forecast | G26: 2.72
B27: PMI (Actual) | C27: 52.7 | F27: Core CPI Current Surprise | G27: =G13-G26 -> 0.18391 | J27: Because of this im wondering if for surprises we should do (Actual - Forecast)/Sdev instead of using the actual stats z score formula because of what it is exactly we want to have the model take into account.
B28: Consensus Forecast | F28: Average Surprise | G28: =AVERAGE('US Macro Data'!U2:U82) -> 0.3830508 | J28: With the regular z scoring it would measure more so how efficient markets are or how well they are pricing information, meaning that worse than expected CPI can end up being positive if the difference is less than the average
B29: Standard Deviation | F29: Standard Deviation | G29: =_xlfn.STDEV.S('US Macro Data'!U2:U82) -> 0.78684
B35: Growth Scoring | F35: Inflation Scoring | J35: Labor Scoring
B36: w(level) | C36: 0.6 | F36: w(level) | G36: 0.6 | J36: w(level) | K36: 0.6
B37: w(surprise) | C37: 0.4 | F37: w(surprise) | G37: 0.4 | J37: W(surprise) | K37: 0.4
B38: direction | C38: 1 | F38: direction | G38: -1 | J38: direction | K38: -1
B40: GDP Score | C40: =(C36*C5)+(C37*C17) -> -0.60866168 | F40: CPI Score | G40: =(G36*G5)+(G37*G17) -> 0.15549999 | J40: Unemployment Score | K40: =(K36*K5)+(K37*K17) -> 0.46564344
B41: PMI Score | C41: =(C36*C11)+(C37*C24) -> 0 | F41: Core CPI Score | G41: =(G36*G11)+(G37*G24) -> -0.0061605771
B44: w(GDP) | C44: 0.3 | F44: w(CPI) | G44: 0.6 | J44: w(unemployment) | K44: 1
B45: w(PMI) | C45: 0.7 | F45: w(Core CPI) | G45: 0.4
B46: Growth Score | C46: =(C44*C40)+(C45*C41) -> -0.1825985 | F46: Inflation Score | G46: =(G44*G40)+(G45*G41) -> 0.090835766 | J46: Unemployment Score | K46: =K44*K40 -> 0.46564344
B49: w(Growth) | C49: 0.4
B50: w(Inflation) | C50: 0.3
B51: w(Unemployment) | C51: 0.3
B52: US Macro Score | C52: =(C49*C46)+(C50*G46)+(C51*K46) -> 0.093904361

Sheet Japan Macro Data
A1: Date (Quarterly) | B1: GDP YoY % Change | C1: PMI | D1: CPI | E1: Core CPI | F1: Unemployment Levels % | I1: Consensus Forecast | K1: GDP | L1: PMI | M1: CPI | N1: Core CPI | O1: Unemployment
A2: 38718 | B2: 2.23718 | F2: 4.4
A3: 38808 | B3: 1.54416 | F3: 4.1
A4: 38899 | B4: 0.62257 | F4: 4.1
A5: 38991 | B5: 1.68977 | F5: 4.1
A6: 39083 | B6: 2.34146 | F6: 4
A7: 39173 | B7: 2.21676 | F7: 3.8
A8: 39264 | B8: 1.5592 | F8: 3.6
A9: 39356 | B9: 0.78191 | F9: 4
A10: 39448 | B10: 0.27216 | F10: 3.9
A11: 39539 | B11: -0.3633 | F11: 3.9
A12: 39630 | B12: -0.82117 | F12: 3.9
A13: 39722 | B13: -3.72138 | F13: 3.8
... A81: 45931 | B81: 0.53886 | F81: 2.6
F82: 2.7

Sheet Japan Macro Scoring

Sheet ECB
A1: Date | B1: Quarter | C1: GDP Growth | D1: HICP (CPI) | E1: Core HICP | F1: Unemployment | H1: Consensus Forecasts | K1: GDP | L1: HICP | M1: Core HICP | N1: Unemployment
A2: 38807 | B2: 2006Q1 | C2: 0.9 | D2: 2.3 | E2: 1.2 | F2: 8.9 | K2: 1.96 | L2: 1.86 | N2: 8.62
A3: 38898 | B3: 2006Q2 | C3: 1.1 | D3: 2.5 | E3: 1.4 | F3: 8.6 | K3: 1.96 | L3: 1.86 | N3: 8.62
A4: 38990 | B4: 2006Q3 | C4: 0.5 | D4: 2.2 | E4: 1.5 | F4: 8.4 | K4: 1.96 | L4: 1.86 | N4: 8.62
A5: 39082 | B5: 2006Q4 | C5: 1.2 | D5: 1.8 | E5: 1.5 | F5: 8.2 | K5: 1.96 | L5: 1.86 | N5: 8.62
A6: 39172 | B6: 2007Q1 | C6: 0.7 | D6: 1.9 | E6: 1.8 | F6: 7.9 | K6: 2.15 | L6: 1.81 | N6: 7.88
A7: 39263 | B7: 2007Q2 | C7: 0.7 | D7: 1.9 | E7: 1.9 | F7: 7.7 | K7: 2.15 | L7: 1.81 | N7: 7.88
A8: 39355 | B8: 2007Q3 | C8: 0.4 | D8: 1.9 | E8: 1.9 | F8: 7.6 | K8: 2.15 | L8: 1.81 | N8: 7.88
A9: 39447 | B9: 2007Q4 | C9: 0.5 | D9: 2.9 | E9: 1.9 | F9: 7.4 | K9: 2.15 | L9: 1.81 | N9: 7.88
A10: 39538 | B10: 2008Q1 | C10: 0.6 | D10: 3.4 | E10: 1.8 | F10: 7.3 | K10: 1.84 | L10: 1.88 | N10: 6.94
A11: 39629 | B11: 2008Q2 | C11: -0.5 | D11: 3.7 | E11: 1.7 | F11: 7.5 | K11: 1.84 | L11: 1.88 | N11: 6.94
A12: 39721 | B12: 2008Q3 | C12: -0.5 | D12: 3.9 | E12: 1.8 | F12: 7.6 | K12: 1.84 | L12: 1.88 | N12: 6.94
A13: 39813 | B13: 2008Q4 | C13: -1.7 | D13: 2.3 | E13: 1.9 | F13: 8 | K13: 1.84 | L13: 1.88 | N13: 6.94
... A44: 42643 | B44: 2016Q3 | C44: 0.5 | D44: 0.3 | E44: 0.8 | F44: 9.9 | K44: 1.68 | L44: 1.35 | N44: 10.59
A45: 42735 | B45: 2016Q4 | C45: 0.8 | D45: 0.7 | E45: 0.8 | F45: 9.8 | K45: 1.68 | L45: 1.35 | M45: 0.9 | N45: 10.59
A46: 42825 | B46: 2017Q1 | C46: 0.8 | D46: 1.7 | E46: 0.8 | F46: 9.5 | K46: 1.54 | L46: 1.53 | M46: 1.1 | N46: 9.7
A47: 42916 | B47: 2017Q2 | C47: 0.7 | D47: 1.5 | E47: 1.1 | F47: 9.2 | K47: 1.54 | L47: 1.53 | M47: 1 | N47: 9.7
A48: 43008 | B48: 2017Q3 | C48: 0.7 | D48: 1.5 | E48: 1.2 | F48: 9 | K48: 1.54 | L48: 1.53 | M48: 1.1 | N48: 9.7
A49: 43100 | B49: 2017Q4 | C49: 0.8 | D49: 1.4 | E49: 0.9 | F49: 8.7 | K49: 1.54 | L49: 1.53 | M49: 1.1 | N49: 9.7
A50: 43190 | B50: 2018Q1 | C50: 0 | D50: 1.3 | E50: 1 | F50: 8.6 | K50: 2.26 | L50: 1.45 | M50: 1.2 | N50: 9.05
A51: 43281 | B51: 2018Q2 | C51: 0.5 | D51: 1.7 | E51: 1 | F51: 8.3 | K51: 2.26 | L51: 1.45 | M51: 1.2 | N51: 9.05
A52: 43373 | B52: 2018Q3 | C52: 0.1 | D52: 2.1 | E52: 1 | F52: 8 | K52: 2.26 | L52: 1.45 | M52: 1.2 | N52: 9.05
A53: 43465 | B53: 2018Q4 | C53: 0.5 | D53: 1.9 | E53: 1 | F53: 7.9 | K53: 2.26 | L53: 1.45 | M53: 1.1. | N53: 9.05
A54: 43555 | B54: 2019Q1 | C54: 0.7 | D54: 1.4 | E54: 1 | F54: 7.8 | K54: 1.53 | L54: 1.63 | M54: 1.3 | N54: 7.86
A55: 43646 | B55: 2019Q2 | C55: 0.4 | D55: 1.4 | E55: 1.1 | F55: 7.6 | K55: 1.53 | L55: 1.63 | M55: 1.2 | N55: 7.86
A56: 43738 | B56: 2019Q3 | C56: 0.2 | D56: 0.9 | E56: 0.9 | F56: 7.4 | K56: 1.53 | L56: 1.63 | M56: 1.1 | N56: 7.86
A57: 43830 | B57: 2019Q4 | C57: -0.1 | D57: 1 | E57: 1.2 | F57: 7.4 | K57: 1.53 | L57: 1.63 | M57: 1.1. | N57: 7.86
A58: 43921 | B58: 2020Q1 | C58: -3.2 | D58: 1.1 | E58: 1.1 | F58: 7.3 | K58: 1.05 | L58: 1.74 | M58: 1.2 | N58: 7.58
A59: 44012 | B59: 2020Q2 | C59: -11.1 | D59: 0.2 | E59: 0.9 | F59: 7.7 | K59: 1.05 | L59: 1.74 | M59: 0.8 | N59: 7.58
A60: 44104 | B60: 2020Q3 | C60: 11.5 | D60: 0 | E60: 0.6 | F60: 8.5 | K60: 1.05 | L60: 1.74 | M60: 0.8 | N60: 7.58
A61: 44196 | B61: 2020Q4 | C61: 0.4 | D61: -0.3 | E61: 0.2 | F61: 8.3 | K61: 1.05 | L61: 1.74 | M61: 0.7 | N61: 7.58
A62: 44286 | B62: 2021Q1 | C62: 0.8 | D62: 1 | E62: 1.1 | F62: 8.2 | K62: 4.37 | L62: 1.43 | M62: 0.8 | N62: 8.87
A63: 44377 | B63: 2021Q2 | C63: 2.2 | D63: 1.8 | E63: 0.8 | F63: 8.1 | K63: 4.37 | L63: 1.43 | M63: 1.1 | N63: 8.87
A64: 44469 | B64: 2021Q3 | C64: 1.8 | D64: 2.9 | E64: 1.4 | F64: 7.5 | K64: 4.37 | L64: 1.43 | M64: 1.2 | N64: 8.87
A65: 44561 | B65: 2021Q4 | C65: 0.8 | D65: 4.7 | E65: 2.4 | F65: 7.1 | K65: 4.37 | L65: 1.43 | M65: 1.4 | N65: 8.87
A66: 44651 | B66: 2022Q1 | C66: 0.7 | D66: 6.1 | E66: 2.7 | F66: 6.8 | K66: 4.19 | L66: 1.26 | M66: 2 | N66: 8.07
A67: 44742 | B67: 2022Q2 | C67: 0.9 | D67: 8.1 | E67: 3.7 | F67: 6.7 | K67: 4.19 | L67: 1.26 | M67: 2.9 | N67: 8.07
A68: 44834 | B68: 2022Q3 | C68: 0.5 | D68: 9.3 | E68: 4.3 | F68: 6.7 | K68: 4.19 | L68: 1.26 | M68: 3.6 | N68: 8.07
A69: 44926 | B69: 2022Q4 | C69: -0.1 | D69: 10 | E69: 5.1 | F69: 6.7 | K69: 4.19 | L69: 1.26 | M69: 4 | N69: 8.07
... A81: 46022 | B81: 2025Q4 | C81: 0.2 | D81: 2.1 | E81: 2.4 | F81: 6.3 | K81: 1.01 | L81: 2.11 | M81: 2.4 | N81: 6.56
...

Sheet ECB Macro Scoring 
B3: Growth Scoring | F3: Inflation Scoring | J3: Labor Scoring
B5: Level (GDP) Score | C5: =(((C7-C8)/C9)*C38) -> -0.41802289 | F5: Level (CPI) Score | G5: =((G7-G8)/G9)*G38 -> 0.063276291 | J5: Level (Unemployment) | K5: =(((K7-K8)/K9)*K38) -> 0.63601115
B7: GDP (Actual) | C7: 1.10765 | F7: CPI (Actual) | G7: 2.434 | J7: Unemployment (Actual) | K7: 4.4
B8: Historical Average | C8: =AVERAGE('US Macro Data'!B2:B81) -> 2.0449501 | F8: Historical Average | G8: =AVERAGE('US Macro Data'!D2:D81) -> 2.5539266 | J8: Historical Average | K8: =AVERAGE('US Macro Data'!F2:F81) -> 5.77125
B9: Standard Deviation | C9: =_xlfn.STDEV.S('US Macro Data'!B2:B81) -> 2.242222 | F9: Standard Deviation | G9: =_xlfn.STDEV.S('US Macro Data'!D2:D81) -> 1.8952853 | J9: Standard Deviation | K9: =_xlfn.STDEV.S('US Macro Data'!F2:F81) -> 2.1560157
B11: Level (PMI) Score | F11: Level (Core CPI) Score | G11: =(((G13-G14)/G15)*G38) -> -0.17899384
B13: PMI (Actual) | C13: 52.7 | F13: Core CPI (Actual) | G13: 2.90391
B14: Historical Average | C14: =AVERAGE('US Macro Data'!C2:C81) -> #DIV/0! | F14: Historical Average | G14: =AVERAGE('US Macro Data'!E2:E81) -> 2.6885889
B15: Standard Deviation | C15: =_xlfn.STDEV.S('US Macro Data'!C2:C81) -> #DIV/0! | F15: Standard Deviation | G15: =_xlfn.STDEV.S('US Macro Data'!E2:E81) -> 1.2029524
B17: Surprise (GDP) Score | C17: =((C20-C21)/C22)*C38 -> -0.89461986 | F17: Surprise (CPI) Score | G17: =((G20-G21)/G22)*G38 -> 0.29383555 | J17: Surprise (Unemployment) | K17: =(((K20-K21)/K22)) -> 0.21009188
B19: GDP Forecast | C19: 4.992656 | F19: CPI Forecast | G19: 2.69 | J19: Unemployment Forecast | K19: 4.42
B20: GDP Current Surprise | C20: =C7-C19 -> -3.885006 | F20: CPI Current Surprise | G20: =G7-G19 -> -0.256 | J20: Unemployment Current Surprise | K20: =K7-K19 -> -0.02
B21: Average Surprise | C21: =AVERAGE('US Macro Data'!R2:R82) -> -2.5690145 | F21: Average Surprise | G21: =AVERAGE('US Macro Data'!T2:T82) -> 0.21054481 | J21: Average Surprise | K21: =AVERAGE('US Macro Data'!V2:V82) -> -0.14790123
B22: Standard Deviation | C22: =_xlfn.STDEV.S('US Macro Data'!K2:K82) -> 1.4710064 | F22: Standard Deviation | G22: =_xlfn.STDEV.S('US Macro Data'!M2:M82) -> 1.5877753 | J22: Standard Deviation | K22: =_xlfn.STDEV.S('US Macro Data'!V2:V82) -> 0.60878715
B24: Surprise (PMI) Score | F24: Surprise (Core CPI) Score | G24: =((G27-G28)/G29)*G38 -> 0.25308932 | J24: Unemployment is unique case because directional variable is -1 but its average is negative
J25: In this case the actual was less forecast and the double negative makes it positive but the directional variable makes it negative again even though this lower than expected unemployment is positive for the macro environment
F26: Core CPI Forecast | G26: 2.72
B27: PMI (Actual) | C27: 52.7 | F27: Core CPI Current Surprise | G27: =G13-G26 -> 0.18391 | J27: Because of this im wondering if for surprises we should do (Actual - Forecast)/Sdev instead of using the actual stats z score formula because of what it is exactly we want to have the model take into account.
B28: Consensus Forecast | F28: Average Surprise | G28: =AVERAGE('US Macro Data'!U2:U82) -> 0.3830508 | J28: With the regular z scoring it would measure more so how efficient markets are or how well they are pricing information, meaning that worse than expected CPI can end up being positive if the difference is less than the average
B29: Standard Deviation | F29: Standard Deviation | G29: =_xlfn.STDEV.S('US Macro Data'!U2:U82) -> 0.78684
B35: Growth Scoring | F35: Inflation Scoring | J35: Labor Scoring
B36: w(level) | C36: 0.6 | F36: w(level) | G36: 0.6 | J36: w(level) | K36: 0.6
B37: w(surprise) | C37: 0.4 | F37: w(surprise) | G37: 0.4 | J37: W(surprise) | K37: 0.4
B38: direction | C38: 1 | F38: direction | G38: -1 | J38: direction | K38: -1
B40: GDP Score | C40: =(C36*C5)+(C37*C17) -> -0.60866168 | F40: CPI Score | G40: =(G36*G5)+(G37*G17) -> 0.15549999 | J40: Unemployment Score | K40: =(K36*K5)+(K37*K17) -> 0.46564344
B41: PMI Score | C41: =(C36*C11)+(C37*C24) -> 0 | F41: Core CPI Score | G41: =(G36*G11)+(G37*G24) -> -0.0061605771
B44: w(GDP) | C44: 0.3 | F44: w(CPI) | G44: 0.6 | J44: w(unemployment) | K44: 1
B45: w(PMI) | C45: 0.7 | F45: w(Core CPI) | G45: 0.4
B46: Growth Score | C46: =(C44*C40)+(C45*C41) -> -0.1825985 | F46: Inflation Score | G46: =(G44*G40)+(G45*G41) -> 0.090835766 | J46: Unemployment Score | K46: =K44*K40 -> 0.46564344
B49: w(Growth) | C49: 0.4
B50: w(Inflation) | C50: 0.3
B51: w(Unemployment) | C51: 0.3
B52: US Macro Score | C52: =(C49*C46)+(C50*G46)+(C51*K46) -> 0.093904361

Sheet Documentation
A1: Consensus Forecasts From Survey of Professional Forecasters
A3: GDP: | C3: PMI: | E3: CPI | G3: Core CPI | I3: Unemployment
A4: NGDP_Growth | E4: Mean CPI Level | G4: Mean Core CPI Level | I4: Mean Unemployment Level
A5: Forecasts for the quarterly and annual level of nominal GDP. Seasonally adjusted, annual rate, billions $. Prior to 1992, these are forecasts for nominal GNP. Annual forecasts are for the annual average of the quarterly levels. | E5: Forecasts for the headline CPI inflation rate. Seasonally adjusted, annual rate, percentage points. Quarterly forecasts are annualized quarter-overquarter percent changes of the quarterly average price index level. Annual forecasts are fourth-quarter over fourth-quarter percent changes. The quarterly price index level is the quarterly average of the underlying monthly price index levels. | G5: Forecasts for the core CPI inflation rate. Seasonally adjusted, annual rate, percentage points. Quarterly forecasts are annualized quarter-over-quarter percent changes of the quarterly average price index level. Annual forecasts are fourth-quarter over fourth-quarter percent changes. The quarterly price index level is the quarterly average of the underlying monthly price index levels. | I5: Forecasts for the quarterly average and annual-average unemployment rate. Seasonally adjusted, percentage points. Quarterly forecasts are for the quarterly average of the underlying monthly levels. Annual forecasts are for the annual average of the underlying monthly levels.
A6: Note: Formula to calculate % change YoY w/ quarterly forecasts Ex. | E6: Took Data from next quarter's projection | G6: Took Data from next quarter's projection | I6: Took Data from next quarter's projection
A7: Data from 2025Q1:
A8: %Change = ((2025Q2 Proj / 400 + 1)*(2025Q3 Proj / 400 +1) *(2025Q4 Proj / 400 + 1) * (2026Q1 Proj / 400 + 1) -1) *100)
A13: ECB
A14: GDP: | E14: HICP Forecast: | G14: Core Inflation | I14: Unemployment
A16: Euro area - Real GDP growth - Average of Point forecasts - Target period ends 12 months after survey cycle begins, Euro area, Annual | E16: HICP Inflation - Average of Point forecasts - Target period ends 27 months after survey cycle begins, Euro area | G16: Euro area - Core inflation - Average of Point forecasts - Target period ends 33 months after survey cycle begins, Euro area, Annual | I16: Euro area - Unemployment rate - Average of Point forecasts - Target period ends 21 months after survey cycle begins (SPF.A.U2.UNEM.POINT.P21M.Q.AVG)
